Workbook

Sheet Summary
B2: Bank Reconciliation - LAKESHORE UNIVERSITY , LLC
B3: WFB Account number 4121510457
B4: 45901
B5: Bank Information
F7: Balance per bank at the month end | H7: 0
B9: Outstanding Bank Deposits:
B12: Outstanding Bank Disbursement:
B14: 09/30/2025 | C14: AP | E14: STAGECOACH SWEEP DEBIT | G14: -455713.94
F16: Outstanding Items Total | H16: =SUM(G11:G14) -> -455713.94
F18: Adjusted bank balance | H18: =+H7-H16 -> 455713.94
B20: General Ledger Information - 11100014 LAKESHORE UNIVERSITY LLC - WFB
F22: Balance per TB at the month end | H22: =GL!I318 -> 222728.21
B24: Un-reconcile Outstanding Deposits:
B27: Un-reconcile Deposits: | D27: Sep' 25
B29: 45929 | C29: AR | D29: J-320131 | E29: Deposit of 09-2025 transfer funds for SD activity | G29: 2187.78
B30: 45929 | C30: AR | D30: J-320135 | E30: PayLease : Cash Deposit 09/29/2025 | G30: 899.73
B31: 45930 | C31: AR | D31: J-320325 | E31: CKS 09/30/2025 Batch 0795459c-c2d8-4c95-84e6-5ba56062a645 | G31: 1735.36
B32: 45930 | C32: AR | D32: J-320325 | E32: CKS 09/30/2025 Batch 58ceb15e-b2cf-463e-8b75-06a3184abba6 | G32: 3495
B33: 45930 | C33: AR | D33: J-320325 | E33: CKS 09/30/2025 Batch 63686773-08b8-442d-ae6d-a114e92eccb1 | G33: 977
B34: 45930 | C34: AR | D34: J-320325 | E34: PayLease : Cash Deposit 09/30/2025 | G34: 914.98
B35: 45930 | C35: AR | D35: J-320325 | E35: RP : CC Deposit 09/30/2025 | G35: 918.72
B36: 45930 | C36: AR | D36: J-325125 | E36: 9.25 PB Free Lot rent-Alafaya Palms OMAR QUINONEZ #173 | G36: 270
F38: Total | G38: =SUM(G27:G37) -> 11398.57
B40: Un-reconciled Outstanding Disbursement:
B43: Un-reconciled Disbursement: | D43: Sep' 25
B45: 45923 | C45: AP | D45: 30779 | E45: Yes Energy Management, Inc. (v0002908) | G45: -63
B46: 45926 | C46: AP | D46: 30780 | E46: Atlas Law (v0000101) | G46: -8358.5
B47: 45929 | C47: AP | D47: 30781 | E47: Charter Communications (v0006510) | G47: -123.95
B48: 45930 | C48: AP | D48: 30783 | E48: Hunter Warfield (v0007270) | G48: -445.75
B49: 45930 | C49: AP | D49: 1446 | E49: Pennoni (v0007120) | G49: -1027.5
B50: 45930 | C50: AP | D50: 1447 | E50: Lakeshore Management Inc (v0000666) | G50: -29.82
B51: 45930 | C51: AP | D51: J-320322 | E51: Lakeshore University LLC mtg pymt | G51: -193875.17
B52: 45930 | C52: AP | D52: J-323192 | E52: Park Mgmt Fees Sept 2025 :Reversed by J-323339 | G52: -22690.01
B53: 45930 | C53: AP | D53: J-325227 | E53: MA September Cash Park to Home :Reversed by J-325304 | G53: -17770.6
F55: Total | G55: =SUM(G45:G54) -> -244384.3
F57: Sub-Total | G57: =SUM(G55+G38) -> -232985.73
F59: Adjusted book balance | H59: =+H22-G57 -> 455713.94
F61: Variance (s/b zero) | H61: =+H18-H59 -> 0

Sheet Summary old
B2: Bank Reconciliation - LAKESHORE UNIVERSITY , LLC
B3: WFB Account number 4121510457
B4: 45261
B5: Bank Information
F7: Balance per bank at the month end | H7: 0
B9: Outstanding Bank Deposits:
B11: 07/31/2023 | C11: AR | E11: ONLINE TRANSFER WTR7 5 REF #BB0K9HKR4L | G11: 240 | I11: email Pejman 1/31/24 | J11: =G11+G12 -> 720
B12: 08/31/2023 | C12: AR | E12: ONLINE TRANSFER LSM TO ALAFAYA WT 8 6 REF #BB0KL2BCD4 | G12: 480 | I12: email Pejman 1/31/24
B14: Outstanding Bank Disbursement:
B16: 12/29/2023 | C16: AP | E16: STAGECOACH SWEEP DEBIT | G16: -554688.4
F18: Outstanding Items Total | H18: =SUM(G11:G16) -> -553968.4
F20: Adjusted bank balance | H20: =+H7-H18 -> 553968.4
B22: General Ledger Information - 11100014 LAKESHORE UNIVERSITY LLC - WFB
F24: Balance per TB at the month end | H24: =+GL!I318 -> 222728.21
B26: Un-reconcile Outstanding Deposits:
B28: 45126 | C28: AR | D28: J-199897 | E28: Credit Card Deposit 07/19/2023 | G28: 30 | I28: emailed Pejman 1/31/24 | J28: =SUM(G28:G37) -> 660
B29: 45127 | C29: AR | D29: J-200511 | E29: Credit Card Deposit 07/20/2023 | G29: 30 | I29: emailed Pejman 1/31/24
B30: 45133 | C30: AR | D30: J-201049 | E30: Credit Card Deposit 07/26/2023 | G30: 60 | I30: emailed Pejman 1/31/24
B31: 45140 | C31: AR | D31: J-202864 | E31: Credit Card Deposit 08/02/2023 | G31: 60 | I31: emailed Pejman 1/31/24
B32: 45147 | C32: AR | D32: J-203316 | E32: Credit Card Deposit 08/09/2023 | G32: 120 | I32: emailed Pejman 1/31/24
B33: 45155 | C33: AR | D33: J-204518 | E33: Credit Card Deposit 08/17/2023 | G33: 180 | I33: emailed Pejman 1/31/24
B34: 45162 | C34: AR | D34: J-204827 | E34: Credit Card Deposit 08/24/2023 | G34: 30 | I34: emailed Pejman 1/31/24
B35: 45182 | C35: AR | D35: J-206474 | E35: Credit Card Deposit 09/13/2023 | G35: 60 | I35: emailed Pejman 1/31/24
B36: 45224 | C36: AR | D36: J-211820 | E36: Credit Card Deposit 10/25/2023 | G36: 60 | I36: emailed Pejman 1/31/24
B37: 45230 | C37: AR | D37: J-212451 | E37: Credit Card Deposit 10/31/2023 | G37: 30 | I37: emailed Pejman 1/31/24
B38: 45288 | C38: AR | D38: J-218048 | E38: PayLease : Cash Deposit 12/28/2023 | G38: 841.51 | I38: to clear Jan 2024
B39: 45291 | C39: AR | D39: J-217534 | E39: Lot 243 Pablo Javier Cruz SD credit to ledger | G39: 675 | I39: to clear Jan 2024
B40: 45291 | C40: AR | D40: J-217534 | E40: Lot 337 Lateja Renae Littles SD credit to ledger | G40: 3590 | I40: to clear Jan 2024
... B47: 45291 | C47: AR | D47: J-219857 | E47: PayLease : Cash Deposit 12/31/2023 | G47: 801.51 | I47: to clear Jan 2024
F49: Total | G49: =SUM(G28:G47) -> 16591.3
B51: Un-reconciled Outstanding Disbursement:
B53: 45097 | C53: AP | D53: 29657 | E53: BALLOONS BY RENEE (v0000109) | G53: -25.09
B54: 45163 | C54: AP | D54: 29765 | E54: John Pierre Martinez Ramos (v0007935) | G54: -3.09
B55: 45257 | C55: AP | D55: 29904 | E55: SHEAFFER INDUSTRIES (v0000974) | G55: -27000
B56: 45271 | C56: AP | D56: 29922 | E56: Communications Consulting Group, Inc. (v0008172) | G56: -234.14
B57: 45275 | C57: AP | D57: 29929 | E57: Communications Consulting Group, Inc. (v0008172) | G57: -36.98
B58: 45278 | C58: AP | D58: 29930 | E58: AtlasLaw (v0000101) | G58: -1004.27
B59: 45279 | C59: AP | D59: 29935 | E59: SHEAFFER INDUSTRIES (v0000974) | G59: -3650
B60: 45281 | C60: AP | D60: 29936 | E60: BALLOONS BY RENEE (v0000109) | G60: -25.09
B61: 45281 | C61: AP | D61: 29939 | E61: CREATIVE MULTICARE, INC. (v0001308) | G61: -200
...

Sheet AR Notes
B2: Bank Reconciliation - LAKESHORE UNIVERSITY , LLC
B3: WFB Account number 4121510457
B4: 44652
B5: Bank Information
F7: Balance per bank at the month end | H7: 359290.86
B9: Outstanding Bank Deposits:
B11: 04/16/2021 | C11: AR | E11: Alafaya Palms - Settlement 041621 000011037449954 Lakeshore Management I 9000631441 000011037449954 R00000091004259204180 | G11: 483.07 | I11: Researching
B12: 04/27/2022 | C12: AR | E12: DESKTOP CHECK DEPOSIT | G12: 86517
B14: Outstanding Bank Disbursement:
F17: Outstanding Items Total | H17: =SUM(G11:G15) -> 87000.07
F19: Adjusted bank balance | H19: =+H7-H17 -> 272290.79
B21: General Ledger Information - 11100014 LAKESHORE UNIVERSITY LLC - WFB
F23: Balance per TB at the month end | H23: =+GL!I318 -> 222728.21
B25: Un-reconcile Outstanding Deposits:
B27: 44302 | C27: AR | D27: J-114439 | E27: RP : ACH Deposit 04/15/2021 | G27: 1442.8 | I27: $717.80 returned on 4/21/21, how was that debit cleared?
B29: Un-reconcile Deposits: | D29: Apr '22 | G29: =+GL!G321 -> 11398.57
F31: Total | G31: =SUM(G26:G30) -> 12841.37
B33: Un-reconciled Outstanding Disbursement:
B36: Un-reconcile Disbursements: | D36: Apr '22 | G36: =+GL!G323 -> -244384.3
F38: Total | G38: =SUM(G34:G37) -> -244384.3
F40: Sub-Total | G40: =SUM(G38+G31) -> -231542.93
F42: Adjusted book balance | H42: =+H23-G40 -> 454271.14
F44: Variance (s/b zero) | H44: =+H19-H42 -> -181980.35

Sheet Bank Statement
A1: Date | B1: Amount | C1: Check Number | D1: Code | E1: Description
A2: 09/02/2025 | B2: -409963.39 | D2: -4 | E2: STAGECOACH SWEEP DEBIT
A3: 09/02/2025 | B3: -165.52 | D3: -3 | E3: 014APOC BILL PAY 090225 GH3H6K 0000Lakeshore Manage 9000820926 GH3H6K 0R00000091006273434795N
A4: 09/02/2025 | B4: -137.76 | C4: 30754 | D4: -3 | E4: CHECK
A5: 09/02/2025 | B5: 19550.05 | D5: 2 | E5: Alafaya Palms - Settlement 090225 000024843797126 Lakeshore Management I 9000631441 000024843797126 R00000091006274007618N
A6: 09/02/2025 | B6: 2061.1 | D6: 3 | E6: BNKCD SETTLE MERCH DEP 250830 286000000277756 ALAFAYA PALMS MHC 1043763809 286000000277756 R00000091003951022269N
A7: 09/02/2025 | B7: 1013.39 | D7: 2 | E7: STAGECOACH SWEEP INTEREST PAYMENT
A8: 09/02/2025 | B8: 387642.13 | D8: 4 | E8: STAGECOACH SWEEP CREDIT
A9: 09/03/2025 | B9: -480855.79 | D9: -4 | E9: STAGECOACH SWEEP DEBIT
A10: 09/03/2025 | B10: -14864.49 | C10: 30761 | D10: -2 | E10: CHECK
A11: 09/03/2025 | B11: 73440.08 | D11: 2 | E11: Alafaya Palms - Settlement 090325 000024890619870 Lakeshore Management I 9000631441 000024890619870 R00000091004450150607N
A12: 09/03/2025 | B12: 10418.33 | D12: 3 | E12: PAYLEASE.COM CREDIT XXXXX1995 Lakeshore Management, 1273639005 440691995 R00000091003638354122N
A13: 09/03/2025 | B13: 950 | D13: 2 | E13: Alafaya Palms - Settlement 090325 000024881277238 Alafaya Palms - 014 9000632861 000024881277238 R00000091004450078305N
A14: 09/03/2025 | B14: 913.48 | D14: 2 | E14: BNKCD SETTLE MERCH DEP 250903 286000000277756 ALAFAYA PALMS MHC 1043763809 286000000277756 R00000091004559890423N
A15: 09/03/2025 | B15: 35 | D15: 2 | E15: Alafaya Palms - Settlement 090325 000024882182778 Alafaya Palms - 014 9000632861 000024882182778 R00000091004450142105N
A16: 09/03/2025 | B16: 409963.39 | D16: 4 | E16: STAGECOACH SWEEP CREDIT
A17: 09/04/2025 | B17: -500843.98 | D17: -4 | E17: STAGECOACH SWEEP DEBIT
A18: 09/04/2025 | B18: -3454.72 | C18: 30755 | D18: -3 | E18: CHECK
A19: 09/04/2025 | B19: -1307.15 | C19: 30758 | D19: -3 | E19: CHECK
A20: 09/04/2025 | B20: -255 | C20: 30757 | D20: -3 | E20: CHECK
A21: 09/04/2025 | B21: -22951.41 | D21: -2 | E21: ACH ORIGINATION - Alafaya Palms - FILE EDIMN00004 COID LAK3642370 LAK3642370 FILE EDIMN00004 0S00000091003637181557N
A22: 09/04/2025 | B22: 41247.87 | D22: 2 | E22: Alafaya Palms - Settlement 090425 000024906269214 Lakeshore Management I 9000631441 000024906269214 R00000091004036673458N
A23: 09/04/2025 | B23: 3700.48 | D23: 2 | E23: BNKCD SETTLE MERCH DEP 250904 286000000277756 ALAFAYA PALMS MHC 1043763809 286000000277756 R00000091004135252078N
A24: 09/04/2025 | B24: 2737.27 | D24: 2 | E24: PAYLEASE.COM CREDIT XXXXX4821 Lakeshore Management, 1273639005 441304821 R00000091004036529803N
A25: 09/04/2025 | B25: 270 | D25: 3 | E25: Lakeshore Manage BILLPAY 090425 FXH9H3 RMR*IV*8.25 PB Free Lot rent 1**270.00*270.00*0.09000688057 FXH9H3 R00000091004036904526N
A26: 09/04/2025 | B26: 196.85 | D26: 2 | E26: DESKTOP CHECK DEPOSIT
A27: 09/04/2025 | B27: 480855.79 | D27: 4 | E27: STAGECOACH SWEEP CREDIT
A28: 09/05/2025 | B28: -350214.36 | D28: -4 | E28: STAGECOACH SWEEP DEBIT
A29: 09/05/2025 | B29: -198634.81 | D29: -3 | E29: Capital One PAYMENT 090425 Capital One, N.A. 1270882098 0R00000091004531704901N
A30: 09/05/2025 | B30: -2260.69 | D30: -2 | E30: 014APOC BILL PAY 090525 Z6TJ9K 0000Lakeshore Manage 9000820926 Z6TJ9K 0R00000091004531593136N
A31: 09/05/2025 | B31: -1416 | D31: -2 | E31: Alafaya Palms - Return 090525 000024913325246 Lakeshore Management I 9000631441 000024913325246 0R00000091004531574058N
A32: 09/05/2025 | B32: -550 | C32: 30756 | D32: -3 | E32: CHECK
A33: 09/05/2025 | B33: 39168.16 | D33: 2 | E33: Alafaya Palms - Settlement 090525 000024919864994 Lakeshore Management I 9000631441 000024919864994 R00000091004531611849N
A34: 09/05/2025 | B34: 8167.98 | D34: 2 | E34: PAYLEASE.COM CREDIT XXXXX4383 Lakeshore Management, 1273639005 441754383 R00000091004531374020N
A35: 09/05/2025 | B35: 1854.72 | D35: 2 | E35: BNKCD SETTLE MERCH DEP 250905 286000000277756 ALAFAYA PALMS MHC 1043763809 286000000277756 R00000091004539933343N
A36: 09/05/2025 | B36: 970 | D36: 2 | E36: Alafaya Palms - Settlement 090525 000024917574366 Alafaya Palms - 014 9000632861 000024917574366 R00000091004531575543N
A37: 09/05/2025 | B37: 966.94 | D37: 2 | E37: Alafaya Palms - Settlement 090525 000024917574358 Alafaya Palms - 014 9000632861 000024917574358 R00000091004531601057N
A38: 09/05/2025 | B38: 908.08 | D38: 2 | E38: Alafaya Palms - Settlement 090525 000024917574350 Alafaya Palms - 014 9000632861 000024917574350 R00000091004531610936N
A39: 09/05/2025 | B39: 500843.98 | D39: 4 | E39: STAGECOACH SWEEP CREDIT
A40: 09/08/2025 | B40: -477523.6 | D40: -4 | E40: STAGECOACH SWEEP DEBIT
...

Sheet GL
A1: General Ledger
A2: Property: Alafaya Palms (014ap)
A3: Detail Date Range: 09/01/25 - 09/30/25 (accrual basis)
A4: 11100014 LAKESHORE UNIVERSITY LLC - WFB (Bank Account) | I4: 146158.5
A5: Property Name | B5: Date | C5: Control | D5: Reference | E5: Description | F5: Remarks | G5: Debit | H5: Credit | I5: Balance | J5: Reconcile Date | K5: Code
A6: Alafaya Palms | B6: 45901 | C6: J-313627 | D6: Daily Deposit | E6: 09/01/2025 Daily Deposit | F6: EFT Deposit 09/01/2025 | G6: 4599.85 | I6: 150758.35 | J6: 09/03/2025 | K6: 2
A7: Alafaya Palms | B7: 45901 | C7: J-313627 | D7: Daily Deposit | E7: 09/01/2025 Daily Deposit | F7: PayLease : Cash Deposit 09/01/2025 | G7: 2772.13 | I7: 153530.48 | J7: 09/03/2025 | K7: 3
A8: Alafaya Palms | B8: 45901 | C8: J-315961 | D8: :Reversal of J-315814 | E8: :Reversal of J-315814 | F8: :Reversal of J-315814 | G8: 22750.99 | I8: 176281.47 | J8: 45900 | K8: 4
A9: Alafaya Palms | B9: 45901 | C9: J-319115 | D9: :Reversal of J-319040 | E9: :Reversal of J-319040 | F9: MA August Cash Park to Home | G9: 21748.98 | I9: 198030.45 | J9: 45900 | K9: 4
A10: Alafaya Palms | B10: 45902 | C10: K-486492 | D10: 1404 | E10: Lakeshore Management Inc (v0000666) | F10: Jun 25 Invoices | H10: -200.42 | I10: 197830.03 | J10: 09/04/2025 | K10: -2
A11: Alafaya Palms | B11: 45902 | C11: K-486671 | D11: 1405 | E11: LSM NT CHECK (v0004320) | F11: Management Fees | H11: -4550.2 | I11: 193279.83 | J11: 09/04/2025 | K11: -2
A12: Alafaya Palms | B12: 45902 | C12: K-486671 | D12: 1405 | E12: LSM NT CHECK (v0004320) | F12: Management Fees | H12: -18200.79 | I12: 175079.04 | J12: 09/04/2025 | K12: -2
A13: Alafaya Palms | B13: 45902 | C13: J-316977 | D13: Daily Deposit | E13: 09/02/2025 Daily Deposit | F13: CKS 09/02/2025 Batch 7c0264bf-524f-4077-8a4c-3890c192799c | G13: 35 | I13: 175114.04 | J13: 09/03/2025 | K13: 2
A14: Alafaya Palms | B14: 45902 | C14: J-316977 | D14: Daily Deposit | E14: 09/02/2025 Daily Deposit | F14: CKS 09/02/2025 Batch aee7890e-a433-413a-8df4-0889c69a7d71 | G14: 950 | I14: 176064.04 | J14: 09/03/2025 | K14: 2
A15: Alafaya Palms | B15: 45902 | C15: J-316977 | D15: Daily Deposit | E15: 09/02/2025 Daily Deposit | F15: PayLease : Cash Deposit 09/02/2025 | G15: 2737.27 | I15: 178801.31 | J15: 09/04/2025 | K15: 2
A16: Alafaya Palms | B16: 45902 | C16: J-316977 | D16: Daily Deposit | E16: 09/02/2025 Daily Deposit | F16: RP : ACH Deposit 08/29/2025 | G16: 19550.05 | I16: 198351.36 | J16: 09/02/2025 | K16: 2
A17: Alafaya Palms | B17: 45902 | C17: J-316977 | D17: Daily Deposit | E17: 09/02/2025 Daily Deposit | F17: RP : CC Deposit 09/02/2025 | G17: 1815.93 | I17: 200167.29 | J17: 09/08/2025 | K17: 2
A18: Alafaya Palms | B18: 45902 | C18: J-319459 | D18: Sweep Interest Payment - September'25 | E18: Sweep Interest Payment - September'25 | F18: Stagecoach Sweep Interest Payment-September'25 | G18: 1013.39 | I18: 201180.68 | J18: 09/02/2025 | K18: 2
A19: Alafaya Palms | B19: 45903 | C19: K-486810 | D19: 30761 | E19: LSE (v0000665) | F19: SEP25 Health Dental | H19: -4168.25 | I19: 197012.43 | J19: 09/03/2025 | K19: -2
A20: Alafaya Palms | B20: 45903 | C20: K-486810 | D20: 30761 | E20: LSE (v0000665) | F20: SEP25 Life STD & OTH | H20: -126.62 | I20: 196885.81 | J20: 09/03/2025 | K20: -2
A21: Alafaya Palms | B21: 45903 | C21: K-486810 | D21: 30761 | E21: LSE (v0000665) | F21: SEP25 Vision | H21: -23.4 | I21: 196862.41 | J21: 09/03/2025 | K21: -2
A22: Alafaya Palms | B22: 45903 | C22: K-486810 | D22: 30761 | E22: LSE (v0000665) | F22: DEPT 15120 ppe 08/30/25 | H22: -182.08 | I22: 196680.33 | J22: 09/03/2025 | K22: -2
A23: Alafaya Palms | B23: 45903 | C23: K-486810 | D23: 30761 | E23: LSE (v0000665) | F23: DEPT 15120 ppe 08/30/25 | H23: -3901.08 | I23: 192779.25 | J23: 09/03/2025 | K23: -2
A24: Alafaya Palms | B24: 45903 | C24: K-486810 | D24: 30761 | E24: LSE (v0000665) | F24: DEPT 15120 ppe 08/30/25 | H24: -6245.26 | I24: 186533.99 | J24: 09/03/2025 | K24: -2
A25: Alafaya Palms | B25: 45903 | C25: K-486810 | D25: 30761 | E25: LSE (v0000665) | F25: DEPT 15120 ppe 08/30/25 | H25: -738.32 | I25: 185795.67 | J25: 09/03/2025 | K25: -2
A26: Alafaya Palms | B26: 45903 | C26: K-486810 | D26: 30761 | E26: LSE (v0000665) | F26: DEPT 15120 ppe 08/30/25 | H26: -91.44 | I26: 185704.23 | J26: 09/03/2025 | K26: -2
A27: Alafaya Palms | B27: 45903 | C27: K-486810 | D27: 30761 | E27: LSE (v0000665) | F27: DEPT 15120 ppe 08/30/25 | G27: 496.8 | I27: 186201.03 | J27: 09/03/2025 | K27: -2
A28: Alafaya Palms | B28: 45903 | C28: K-486810 | D28: 30761 | E28: LSE (v0000665) | F28: DEPT 15120 ppe 08/30/25 | G28: 48.27 | I28: 186249.3 | J28: 09/03/2025 | K28: -2
A29: Alafaya Palms | B29: 45903 | C29: K-486810 | D29: 30761 | E29: LSE (v0000665) | F29: DEPT 15120 ppe 08/30/25 | G29: 80.45 | I29: 186329.75 | J29: 09/03/2025 | K29: -2
A30: Alafaya Palms | B30: 45903 | C30: K-486810 | D30: 30761 | E30: LSE (v0000665) | F30: DEPT 15120 ppe 08/30/25 | G30: 14.96 | I30: 186344.71 | J30: 09/03/2025 | K30: -2
A31: Alafaya Palms | B31: 45903 | C31: K-486810 | D31: 30761 | E31: LSE (v0000665) | F31: DEPT 35200 ppe 08/30/25 | H31: -26.5 | I31: 186318.21 | J31: 09/03/2025 | K31: -2
A32: Alafaya Palms | B32: 45903 | C32: K-486810 | D32: 30761 | E32: LSE (v0000665) | F32: DEPT 35200 ppe 08/30/25 | H32: -2.02 | I32: 186316.19 | J32: 09/03/2025 | K32: -2
A33: Alafaya Palms | B33: 45903 | C33: J-317122 | E33: PDM & Hunter Warfield | F33: PROFESSIONAL DEBT MEDIATION CAROL J. WATSON PERIOD ENDING 6/16/25 TO 7/15/25 | G33: 12 | I33: 186328.19 | J33: 09/04/2025 | K33: 2
A34: Alafaya Palms | B34: 45903 | C34: J-317122 | E34: PDM & Hunter Warfield | F34: HUNTER WARFIELD ELIZABETH CABRERA RIVERA PERIOD ENDING 7/31/25 | G34: 184.85 | I34: 186513.04 | J34: 09/04/2025 | K34: 2
A35: Alafaya Palms | B35: 45903 | C35: J-318699 | D35: Daily Deposit | E35: 09/03/2025 Daily Deposit | F35: PayLease : Cash Deposit 09/03/2025 | G35: 8167.98 | I35: 194681.02 | J35: 09/05/2025 | K35: 2
A36: Alafaya Palms | B36: 45903 | C36: J-318699 | D36: Daily Deposit | E36: 09/03/2025 Daily Deposit | F36: RP : ACH Deposit 08/29/2025 | G36: 1416 | I36: 196097.02 | J36: 09/03/2025 | K36: 2
A37: Alafaya Palms | B37: 45903 | C37: J-318699 | D37: Daily Deposit | E37: 09/03/2025 Daily Deposit | F37: RP : ACH Deposit 08/30/2025 | G37: 3696.26 | I37: 199793.28 | J37: 09/03/2025 | K37: 2
A38: Alafaya Palms | B38: 45903 | C38: J-318699 | D38: Daily Deposit | E38: 09/03/2025 Daily Deposit | F38: RP : ACH Deposit 08/31/2025 | G38: 16883.99 | I38: 216677.27 | J38: 09/03/2025 | K38: 2
A39: Alafaya Palms | B39: 45903 | C39: J-318699 | D39: Daily Deposit | E39: 09/03/2025 Daily Deposit | F39: RP : ACH Deposit 09/01/2025 | G39: 26941.26 | I39: 243618.53 | J39: 09/03/2025 | K39: 2
A40: Alafaya Palms | B40: 45903 | C40: J-318699 | D40: Daily Deposit | E40: 09/03/2025 Daily Deposit | F40: RP : ACH Deposit 09/02/2025 | G40: 19902.72 | I40: 263521.25 | J40: 09/03/2025 | K40: 2
...

Sheet Un-Reconcile transactions
A1: Bank
A2: Property Name | B2: Date | C2: Control | D2: Reference | E2: Description | F2: Remarks | G2: Amount | H2: Comment
A3: Alafaya Palms | B3: 09/30/2025 | F3: STAGECOACH SWEEP DEBIT | G3: -455713.94 | H3: AP | I3: Will be reversed on 10/01/2025
G4: =SUM(G3:G3) -> -455713.94
A6: GL
A7: Property Name | B7: Date | C7: Control | D7: Reference | E7: Description | F7: Remarks | G7: Amount | H7: Comment
A8: Alafaya Palms | B8: 45929 | C8: J-320131 | D8: Deposit of 09-2025 transfer funds for SD activity | E8: Deposit of 09-2025 transfer funds for SD activity | F8: Deposit of 09-2025 transfer funds for SD activity | G8: 2187.78 | H8: AR | I8: Will clear on 10/03/2025 with bank transaction
A9: Alafaya Palms | B9: 45929 | C9: J-320135 | D9: Daily Deposit | E9: 09/29/2025 Daily Deposit | F9: PayLease : Cash Deposit 09/29/2025 | G9: 899.73 | H9: AR | I9: Will clear on 10/01/2025 with bank transaction
A10: Alafaya Palms | B10: 45930 | C10: J-320325 | D10: Daily Deposit | E10: 09/30/2025 Daily Deposit | F10: CKS 09/30/2025 Batch 0795459c-c2d8-4c95-84e6-5ba56062a645 | G10: 1735.36 | H10: AR | I10: Will clear on 10/01/2025 with bank transaction
A11: Alafaya Palms | B11: 45930 | C11: J-320325 | D11: Daily Deposit | E11: 09/30/2025 Daily Deposit | F11: CKS 09/30/2025 Batch 58ceb15e-b2cf-463e-8b75-06a3184abba6 | G11: 3495 | H11: AR | I11: Will clear on 10/01/2025 with bank transaction
A12: Alafaya Palms | B12: 45930 | C12: J-320325 | D12: Daily Deposit | E12: 09/30/2025 Daily Deposit | F12: CKS 09/30/2025 Batch 63686773-08b8-442d-ae6d-a114e92eccb1 | G12: 977 | H12: AR | I12: Will clear on 10/01/2025 with bank transaction
A13: Alafaya Palms | B13: 45930 | C13: J-320325 | D13: Daily Deposit | E13: 09/30/2025 Daily Deposit | F13: PayLease : Cash Deposit 09/30/2025 | G13: 914.98 | H13: AR | I13: Will clear on 10/02/2025 with bank transaction
A14: Alafaya Palms | B14: 45930 | C14: J-320325 | D14: Daily Deposit | E14: 09/30/2025 Daily Deposit | F14: RP : CC Deposit 09/30/2025 | G14: 918.72 | H14: AR | I14: Will clear on 10/01/2025 with bank transaction
A15: Alafaya Palms | B15: 45930 | C15: J-325125 | D15: 9.2025 PB Free Lot rent | E15: 9.2025 PB Free Lot rent | F15: 9.25 PB Free Lot rent-Alafaya Palms OMAR QUINONEZ #173 | G15: 270 | H15: AR | I15: Will clear on 10/03/2025 with bank transaction
G16: =SUM(G8:G15) -> 11398.57
A18: Alafaya Palms | B18: 45923 | C18: K-492078 | D18: 30779 | E18: Yes Energy Management, Inc. (v0002908) | F18: Utility Invoice Processing (UEM) 08/01/2025 - 08/31/2025 Inv# 1283008 | G18: -63 | H18: AP | I18: Will clear on 10/02/2025 with bank transaction
A19: Alafaya Palms | B19: 45926 | C19: K-493064 | D19: 30780 | E19: Atlas Law (v0000101) | F19: LOT# 365 RODRIGUEZ FERNANDEZ | G19: -1473.99 | H19: AP | I19: Will clear on 10/06/2025 with bank transaction
A20: Alafaya Palms | B20: 45926 | C20: K-493064 | D20: 30780 | E20: Atlas Law (v0000101) | F20: LOT# 205 DIAZ MORENO | G20: -1325.02 | H20: AP
A21: Alafaya Palms | B21: 45926 | C21: K-493064 | D21: 30780 | E21: Atlas Law (v0000101) | F21: LOT# 305 ARTZBERGER | G21: -532.84 | H21: AP
A22: Alafaya Palms | B22: 45926 | C22: K-493064 | D22: 30780 | E22: Atlas Law (v0000101) | F22: LOT# 345 OQUENDO | G22: -75.74 | H22: AP
A23: Alafaya Palms | B23: 45926 | C23: K-493064 | D23: 30780 | E23: Atlas Law (v0000101) | F23: LOT# 22 TOMKO | G23: -150 | H23: AP
A24: Alafaya Palms | B24: 45926 | C24: K-493064 | D24: 30780 | E24: Atlas Law (v0000101) | F24: LOT# 262 DELIZ | G24: -45 | H24: AP
A25: Alafaya Palms | B25: 45926 | C25: K-493064 | D25: 30780 | E25: Atlas Law (v0000101) | F25: LOT# 206 GREEN | G25: -5.36 | H25: AP
A26: Alafaya Palms | B26: 45926 | C26: K-493064 | D26: 30780 | E26: Atlas Law (v0000101) | F26: LOT# 206 GREEN | G26: -13.04 | H26: AP
A27: Alafaya Palms | B27: 45926 | C27: K-493064 | D27: 30780 | E27: Atlas Law (v0000101) | F27: LOT# 71 MONICK | G27: -100 | H27: AP
A28: Alafaya Palms | B28: 45926 | C28: K-493064 | D28: 30780 | E28: Atlas Law (v0000101) | F28: LOT# 56 ROMAN | G28: -949.59 | H28: AP
A29: Alafaya Palms | B29: 45926 | C29: K-493064 | D29: 30780 | E29: Atlas Law (v0000101) | F29: LOT# 396 VINCENTY | G29: -1231.53 | H29: AP
A30: Alafaya Palms | B30: 45926 | C30: K-493064 | D30: 30780 | E30: Atlas Law (v0000101) | F30: LOT# 218 STAUFFER | G30: -981.37 | H30: AP
A31: Alafaya Palms | B31: 45926 | C31: K-493064 | D31: 30780 | E31: Atlas Law (v0000101) | F31: LOT# 246 LAUREANO | G31: -150 | H31: AP
A32: Alafaya Palms | B32: 45926 | C32: K-493064 | D32: 30780 | E32: Atlas Law (v0000101) | F32: LOT# 82 SANCHEZ-COSME | G32: -1325.02 | H32: AP
A33: Alafaya Palms | B33: 45929 | C33: K-493359 | D33: 30781 | E33: Charter Communications (v0006510) | F33: ACCOUNT# 8337 10 029 1675135 CLUBHOUSE 09/18/2025-10/17/2025 INTERNET SERVICE. | G33: -123.95 | H33: AP | I33: Will clear on 10/09/2025 with bank transaction
A34: Alafaya Palms | B34: 45930 | C34: K-493554 | D34: 30783 | E34: Hunter Warfield (v0007270) | F34: Court Fee Lot 50 Vazquez | G34: -5.95 | H34: AP | I34: Showing outstanding status in bank
A35: Alafaya Palms | B35: 45930 | C35: K-493554 | D35: 30783 | E35: Hunter Warfield (v0007270) | F35: Court Fee Lot 50 Vazquez | G35: -10 | H35: AP
A36: Alafaya Palms | B36: 45930 | C36: K-493554 | D36: 30783 | E36: Hunter Warfield (v0007270) | F36: Court Fee Lot 50 Vazquez | G36: -3 | H36: AP
A37: Alafaya Palms | B37: 45930 | C37: K-493554 | D37: 30783 | E37: Hunter Warfield (v0007270) | F37: Court Fee Lot 500 Cabrera | G37: -184.85 | H37: AP
A38: Alafaya Palms | B38: 45930 | C38: K-493554 | D38: 30783 | E38: Hunter Warfield (v0007270) | F38: Court Fee Lot 220 Gonzalez | G38: -74.95 | H38: AP
A39: Alafaya Palms | B39: 45930 | C39: K-493554 | D39: 30783 | E39: Hunter Warfield (v0007270) | F39: Court Fee Lot 220 Gonzalez | G39: -167 | H39: AP
A40: Alafaya Palms | B40: 45930 | C40: K-493627 | D40: 1446 | E40: Pennoni (v0007120) | F40: TZ-orange county permits | G40: -1027.5 | H40: AP | I40: Will clear on 10/02/2025 with bank transaction
A41: Alafaya Palms | B41: 45930 | C41: K-493746 | D41: 1447 | E41: Lakeshore Management Inc (v0000666) | F41: Batch#78964 Enterprise | G41: -29.82 | H41: AP | I41: Will clear on 10/01/2025 with bank transaction
A42: Alafaya Palms | B42: 45930 | C42: J-320322 | D42: 9/2025 Mortgages 2-40 | E42: 9/2025 Mortgages 2-40 | F42: Lakeshore University LLC mtg pymt | G42: -193875.17 | H42: AP | I42: Will clear on 10/06/2025 with bank transaction
...

Sheet Old Reconciled
A1: Bank
A2: Property name | B2: Date | C2: Amount | D2: Check Number | E2: Description | F2: Remarks | G2: Code
A3: Alafaya Palms | B3: 08/29/2025 | C3: -387642.13 | F3: STAGECOACH SWEEP DEBIT | G3: -4
A5: GL
A6: Property name | B6: Date | C6: Control | D6: Reference | E6: Description | F6: Remarks | G6: Debit | J6: Reconcile Date | K6: Code
A7: Alafaya Palms | B7: 45898 | C7: J-313621 | D7: Daily Deposit | E7: 08/29/2025 Daily Deposit | F7: PayLease : Cash Deposit 08/29/2025 | G7: 6696.14 | J7: 09/03/2025 | K7: 3
A8: Alafaya Palms | B8: 45898 | C8: J-313621 | D8: Daily Deposit | E8: 08/29/2025 Daily Deposit | F8: RP : CC Deposit 08/29/2025 | G8: 2061.1 | J8: 09/02/2025 | K8: 3
A9: Alafaya Palms | B9: 45899 | C9: J-316898 | D9: 8.2025 PB Free Lot rent | E9: 8.2025 PB Free Lot rent | F9: 8.25 PB Free Lot rent-Alafaya Palms OMAR QUINONEZ #173 | G9: 270 | J9: 09/04/2025 | K9: 3
A10: Alafaya Palms | B10: 45900 | C10: J-313626 | D10: Daily Deposit | E10: 08/31/2025 Daily Deposit | F10: PayLease : Cash Deposit 08/31/2025 | G10: 950.06 | J10: 09/03/2025 | K10: 3
A11: Alafaya Palms | B11: 45894 | C11: K-484450 | D11: 30754 | E11: Staples Bus (v0001011) | F11: ORDER# 7663140333-000-001 BY MARILYN GONZALEZ | H11: -137.76 | J11: 09/02/2025 | K11: -3
A12: Alafaya Palms | B12: 45894 | C12: K-484498 | D12: 30755 | E12: Atlas Law (v0000101) | F12: LOT# 71 MONICK | H12: -634.09 | J12: 09/04/2025 | K12: -3
A13: Alafaya Palms | B13: 45894 | C13: K-484498 | D13: 30755 | E13: Atlas Law (v0000101) | F13: LOT# 305 ARTZBERGER | H13: -787.87 | J13: 09/04/2025 | K13: -3
A14: Alafaya Palms | B14: 45894 | C14: K-484498 | D14: 30755 | E14: Atlas Law (v0000101) | F14: LOT# 345 OQUENDO | H14: -451.77 | J14: 09/04/2025 | K14: -3
A15: Alafaya Palms | B15: 45894 | C15: K-484498 | D15: 30755 | E15: Atlas Law (v0000101) | F15: AP vs Calo | H15: -405.99 | J15: 09/04/2025 | K15: -3
A16: Alafaya Palms | B16: 45894 | C16: K-484498 | D16: 30755 | E16: Atlas Law (v0000101) | F16: AP vs Tomko | H16: -300 | J16: 09/04/2025 | K16: -3
A17: Alafaya Palms | B17: 45894 | C17: K-484498 | D17: 30755 | E17: Atlas Law (v0000101) | F17: AP vs Green | H17: -875 | J17: 09/04/2025 | K17: -3
A18: Alafaya Palms | B18: 45894 | C18: K-484499 | D18: 30756 | E18: CENTRAL WATER & ELECTRIC UTILITY SERVICES (v0000190) | F18: BOIL ADVISORY BACTERIOLOGICAL SAMPLES | H18: -550 | J18: 09/05/2025 | K18: -3
A19: Alafaya Palms | B19: 45894 | C19: K-484500 | D19: 30757 | E19: Lutz Bobo & Telfair PA (v0001333) | F19: Prospectus amendments | H19: -255 | J19: 09/04/2025 | K19: -3
A20: Alafaya Palms | B20: 45895 | C20: K-484970 | D20: 30758 | E20: Atlas Law (v0000101) | F20: AP vs Vasquez | H20: -1307.15 | J20: 09/04/2025 | K20: -3
A21: Alafaya Palms | B21: 45895 | C21: K-485115 | D21: 30759 | E21: Yes Energy Management, Inc. (v0002908) | F21: Utility Invoice Processing (UEM) 07/01/2025 - 07/31/2025 Inv# 1265790 | H21: -56 | J21: 09/12/2025 | K21: -3
A22: Alafaya Palms | B22: 45898 | C22: K-485856 | D22: 1403 | E22: DUKE ENERGY (v0000370) | F22: 07/29/2025-08/26/2025-Electric-9101 4870 5160-Electric Outdoor-0 Wesleyan blvd | H22: -165.52 | J22: 09/02/2025 | K22: -3
... A24: Alafaya Palms | B24: 45900 | C24: J-313554 | D24: 8/2025 Mortgages 2-40 | E24: 8/2025 Mortgage Payments 2-40 | F24: Lakeshore University LLC mtg pymt | H24: -198634.81 | J24: 09/05/2025 | K24: -3
A25: Alafaya Palms | B25: 45900 | C25: J-315814 | D25: Park Mgmt Fees Aug 2025 | E25: Park Mgmt Fees Aug 2025 :Reversed by J-315961 | F25: Park Mgmt Fees Aug 2025 :Reversed by J-315961 | H25: -22750.99 | J25: 45901 | K25: -4
A26: Alafaya Palms | B26: 45900 | C26: J-319040 | E26: MA August Cash Park to Home :Reversed by J-319115 | F26: MA August Cash Park to Home | H26: -21748.98 | J26: 45901 | K26: -4
